<?xml version="1.0" ?>
<!-- =================================================================================== -->
<!-- |    This document was autogenerated by xacro from right_leg.xacro                | -->
<!-- |    EDITING THIS FILE BY HAND IS NOT RECOMMENDED                                 | -->
<!-- =================================================================================== -->
<robot name="right_leg" xmlns:xacro="http://ros.org/wiki/xacro">
  <material name="gray">
    <color rgba="0.5 0.5 0.5 2.5"/>
  </material>
  <link name="base_link"/>
  <joint name="right_leg1_joint" type="continuous">
    <origin xyz="0 0.0 0.0"/>
    <parent link="base_link"/>
    <child link="servohead5"/>
    <axis xyz="1 0.0 0.0"/>
  </joint>
  <link name="servohead5">
    <visual>
      <geometry>
        <mesh filename="package://4leg_robot/stl/servohead_part5.stl"/>
      </geometry>
      <material name="gray"/>
    </visual>
  </link>
  <joint name="servohead_joint" type="fixed">
    <parent link="servohead5"/>
    <child link="servohead6"/>
    <origin xyz="0.0 0.015 0.0"/>
  </joint>
  <link name="servohead6">
    <visual>
      <geometry>
        <mesh filename="package://4leg_robot/stl/servohead_part6.stl"/>
      </geometry>
      <material name="grey"/>
    </visual>
  </link>
</robot>

